"""
Comprehensive Error Handling and Edge Case Tests

This test suite provides exhaustive testing of error scenarios and edge cases
for the AI trading bot system, focusing on:

1. Network connectivity issues and timeouts
2. API rate limiting and authentication errors
3. Invalid data handling and malformed responses
4. WebSocket disconnections and recovery
5. Configuration errors and validation
6. Resource exhaustion scenarios
7. Circuit breaker patterns
8. Error propagation and logging
9. Recovery mechanisms
10. Graceful degradation
"""

import asyncio
import json
import logging
import os
import random
import threading
import time
from datetime import UTC, datetime, timedelta
from decimal import Decimal, InvalidOperation
from typing import Any
from unittest.mock import Mock

import aiohttp
import pytest
from websockets import ConnectionClosed, InvalidURI, WebSocketException

from bot.error_handling import (
    BalanceErrorHandler,
    ErrorBoundary,
    ErrorSeverity,
    GracefulDegradation,
    TradeSaga,
    exception_handler,
    retry_with_backoff,
)
from bot.exchange.base import (
    BalanceRetrievalError,
    BalanceServiceUnavailableError,
    BalanceTimeoutError,
    BalanceValidationError,
    InsufficientBalanceError,
)
from bot.fp.effects.error import (
    NetworkError,
    RateLimitError,
    create_error_recovery_strategy,
    with_retry,
)
from bot.fp.effects.io import IOEither
from bot.risk.circuit_breaker import TradingCircuitBreaker
from bot.trading_types import MarketData, Order, OrderStatus, TradeAction

logger = logging.getLogger(__name__)


class NetworkFailureSimulator:
    """Simulates various network failure scenarios."""

    def __init__(self):
        self.failure_mode = "normal"
        self.failure_count = 0
        self.call_count = 0
        self.latency_ms = 0
        self.intermittent_failure_rate = 0.0

    def reset(self):
        """Reset simulator state."""
        self.failure_mode = "normal"
        self.failure_count = 0
        self.call_count = 0
        self.latency_ms = 0
        self.intermittent_failure_rate = 0.0

    def set_failure_mode(self, mode: str, **kwargs):
        """Set specific failure mode."""
        self.failure_mode = mode
        if mode == "timeout":
            self.latency_ms = kwargs.get("timeout_ms", 5000)
        elif mode == "intermittent":
            self.intermittent_failure_rate = kwargs.get("failure_rate", 0.3)
        elif mode == "progressive":
            self.failure_count = 0

    async def simulate_request(self, url: str, **kwargs) -> dict[str, Any]:
        """Simulate HTTP request with failures."""
        self.call_count += 1

        # Add latency if configured
        if self.latency_ms > 0:
            await asyncio.sleep(self.latency_ms / 1000)

        if self.failure_mode == "connection_error":
            raise aiohttp.ClientConnectionError("Connection failed")
        if self.failure_mode == "timeout":
            raise TimeoutError("Request timed out")
        if self.failure_mode == "server_error":
            raise aiohttp.ClientResponseError(
                request_info=Mock(),
                history=(),
                status=500,
                message="Internal Server Error",
            )
        if self.failure_mode == "rate_limit":
            raise aiohttp.ClientResponseError(
                request_info=Mock(),
                history=(),
                status=429,
                message="Rate limit exceeded",
            )
        if self.failure_mode == "intermittent":
            if random.random() < self.intermittent_failure_rate:
                raise aiohttp.ClientConnectionError("Intermittent failure")
        elif self.failure_mode == "progressive":
            self.failure_count += 1
            failure_threshold = 3
            if self.failure_count <= failure_threshold:
                raise aiohttp.ClientConnectionError(
                    f"Progressive failure {self.failure_count}"
                )
        elif self.failure_mode == "malformed_response":
            return {"invalid": "response_structure", "missing_required_fields": True}

        # Normal response
        return {
            "success": True,
            "data": {"timestamp": datetime.now().isoformat()},
            "call_count": self.call_count,
        }


class WebSocketFailureSimulator:
    """Simulates WebSocket failure scenarios."""

    def __init__(self):
        self.connection_mode = "normal"
        self.message_corruption_rate = 0.0
        self.disconnect_after_messages = None
        self.message_count = 0

    def set_connection_mode(self, mode: str, **kwargs):
        """Set WebSocket connection mode."""
        self.connection_mode = mode
        if mode == "message_corruption":
            self.message_corruption_rate = kwargs.get("corruption_rate", 0.2)
        elif mode == "periodic_disconnect":
            self.disconnect_after_messages = kwargs.get("disconnect_after", 5)

    async def simulate_connection(self, uri: str):
        """Simulate WebSocket connection."""
        if self.connection_mode == "connection_refused":
            raise ConnectionRefusedError("Connection refused")
        if self.connection_mode == "invalid_uri":
            raise InvalidURI(uri, "Invalid WebSocket URI")
        if self.connection_mode == "ssl_error":
            raise Exception("SSL handshake failed")

        # Return mock WebSocket connection
        return MockWebSocket(self)


class MockWebSocket:
    """Mock WebSocket for testing."""

    def __init__(self, simulator: WebSocketFailureSimulator):
        self.simulator = simulator
        self.closed = False

    async def send(self, message: str):
        """Send message through WebSocket."""
        if self.closed:
            raise ConnectionClosed(None, None)

        if self.simulator.connection_mode == "send_failure":
            raise WebSocketException("Failed to send message")

    async def recv(self) -> str:
        """Receive message from WebSocket."""
        if self.closed:
            raise ConnectionClosed(None, None)

        self.simulator.message_count += 1

        if (
            self.simulator.disconnect_after_messages
            and self.simulator.message_count >= self.simulator.disconnect_after_messages
        ):
            self.closed = True
            raise ConnectionClosed(None, None)

        if (
            self.simulator.connection_mode == "message_corruption"
            and random.random() < self.simulator.message_corruption_rate
        ):
            return "corrupted_message_data"

        # Normal message
        return json.dumps(
            {
                "type": "market_data",
                "symbol": "BTC-USD",
                "price": 50000.0,
                "timestamp": datetime.now().isoformat(),
            }
        )

    async def close(self):
        """Close WebSocket connection."""
        self.closed = True


class TestNetworkErrorHandling:
    """Test network connectivity issues and timeouts."""

    @pytest.fixture
    def network_simulator(self):
        """Network failure simulator fixture."""
        simulator = NetworkFailureSimulator()
        yield simulator
        simulator.reset()

    @pytest.mark.asyncio
    async def test_connection_timeout_handling(self, network_simulator):
        """Test handling of connection timeouts."""
        network_simulator.set_failure_mode("timeout", timeout_ms=100)

        # Test with retry mechanism
        @retry_with_backoff(
            max_retries=3, base_delay=0.01, exceptions=(asyncio.TimeoutError,)
        )
        async def timeout_operation():
            return await network_simulator.simulate_request("https://api.test.com")

        start_time = datetime.now()
        with pytest.raises(asyncio.TimeoutError):
            await timeout_operation()
        end_time = datetime.now()

        # Should have attempted retries
        assert network_simulator.call_count >= 3
        # Should have taken time for retries
        assert (end_time - start_time).total_seconds() >= 0.03

    @pytest.mark.asyncio
    async def test_connection_refused_handling(self, network_simulator):
        """Test handling of connection refused errors."""
        network_simulator.set_failure_mode("connection_error")

        with pytest.raises(aiohttp.ClientConnectionError) as exc_info:
            await network_simulator.simulate_request("https://api.test.com")

        assert "Connection failed" in str(exc_info.value)

    @pytest.mark.asyncio
    async def test_intermittent_connection_issues(self, network_simulator):
        """Test handling of intermittent connectivity issues."""
        network_simulator.set_failure_mode("intermittent", failure_rate=0.7)

        success_count = 0
        failure_count = 0

        for _ in range(10):
            try:
                await network_simulator.simulate_request("https://api.test.com")
                success_count += 1
            except aiohttp.ClientConnectionError:
                failure_count += 1

        assert failure_count > 0  # Should have some failures
        assert success_count > 0  # Should have some successes

    @pytest.mark.asyncio
    async def test_progressive_failure_recovery(self, network_simulator):
        """Test recovery from progressive failures."""
        network_simulator.set_failure_mode("progressive")

        # First few calls should fail
        for i in range(3):
            with pytest.raises(aiohttp.ClientConnectionError):
                await network_simulator.simulate_request("https://api.test.com")

        # Subsequent calls should succeed
        response = await network_simulator.simulate_request("https://api.test.com")
        assert response["success"] is True

    @pytest.mark.asyncio
    async def test_network_error_with_circuit_breaker(self, network_simulator):
        """Test network errors with circuit breaker pattern."""
        network_simulator.set_failure_mode("connection_error")

        circuit_breaker = TradingCircuitBreaker(failure_threshold=3, timeout_seconds=1)

        # Trigger circuit breaker with network failures
        for _ in range(4):
            if circuit_breaker.can_execute_trade():
                try:
                    await network_simulator.simulate_request("https://api.test.com")
                    circuit_breaker.record_success()
                except aiohttp.ClientConnectionError as e:
                    circuit_breaker.record_failure("network_error", str(e))

        # Circuit should be open
        assert circuit_breaker.state == "OPEN"
        assert not circuit_breaker.can_execute_trade()

        # Wait for timeout and test recovery
        await asyncio.sleep(1.1)
        network_simulator.set_failure_mode("normal")  # Fix network

        assert circuit_breaker.can_execute_trade()  # Should allow half-open

        # Successful operation should close circuit
        response = await network_simulator.simulate_request("https://api.test.com")
        circuit_breaker.record_success()
        assert circuit_breaker.state == "CLOSED"


class TestAPIErrorHandling:
    """Test API rate limiting and authentication errors."""

    @pytest.fixture
    def api_simulator(self):
        """API error simulator fixture."""
        return NetworkFailureSimulator()

    @pytest.mark.asyncio
    async def test_rate_limiting_with_backoff(self, api_simulator):
        """Test handling of API rate limiting with backoff."""
        api_simulator.set_failure_mode("rate_limit")

        # Test functional rate limit error
        rate_limit_error = RateLimitError(
            message="Rate limit exceeded",
            error_code="RATE_LIMIT_429",
            retry_after=timedelta(milliseconds=100),
            limit_type="requests_per_minute",
            current_rate=100,
            max_rate=60,
        )

        # Test retry mechanism respects rate limit timing
        def rate_limited_operation() -> IOEither[Exception, str]:
            return IOEither.left(rate_limit_error)

        start_time = datetime.now()
        result = with_retry(
            operation=rate_limited_operation,
            max_attempts=2,
            delay=rate_limit_error.retry_after,
        )
        end_time = datetime.now()

        # Should respect retry_after timing
        assert (end_time - start_time).total_seconds() >= 0.1

    @pytest.mark.asyncio
    async def test_authentication_errors(self, api_simulator):
        """Test handling of authentication errors."""

        class AuthenticationError(Exception):
            def __init__(self, message: str, error_code: str = "AUTH_ERROR"):
                super().__init__(message)
                self.error_code = error_code

        auth_errors = [
            AuthenticationError("Invalid API key", "INVALID_API_KEY"),
            AuthenticationError("Expired token", "TOKEN_EXPIRED"),
            AuthenticationError("Insufficient permissions", "PERMISSION_DENIED"),
        ]

        # Authentication errors should not be retried
        for auth_error in auth_errors:

            def auth_operation() -> IOEither[Exception, str]:
                return IOEither.left(auth_error)

            # Should not retry auth errors
            def should_retry(error: Exception) -> bool:
                return not isinstance(error, AuthenticationError)

            result = with_retry(
                operation=auth_operation, max_attempts=3, should_retry=should_retry
            )

            # Should fail immediately without retries
            assert result.run().is_left()

    @pytest.mark.asyncio
    async def test_server_error_handling(self, api_simulator):
        """Test handling of server errors (5xx)."""
        api_simulator.set_failure_mode("server_error")

        # Server errors should be retried
        retry_count = 0

        @retry_with_backoff(
            max_retries=3, base_delay=0.01, exceptions=(aiohttp.ClientResponseError,)
        )
        async def server_operation():
            nonlocal retry_count
            retry_count += 1
            await api_simulator.simulate_request("https://api.test.com")

        with pytest.raises(aiohttp.ClientResponseError):
            await server_operation()

        assert retry_count >= 3  # Should have retried

    @pytest.mark.asyncio
    async def test_api_error_aggregation(self, api_simulator):
        """Test aggregation and analysis of API errors."""
        from bot.error_handling import error_aggregator

        # Simulate various API errors
        error_types = ["rate_limit", "server_error", "connection_error"]

        for error_type in error_types:
            for _ in range(3):
                api_simulator.set_failure_mode(error_type)
                try:
                    await api_simulator.simulate_request("https://api.test.com")
                except Exception as e:
                    # Log error with aggregator
                    error_context = exception_handler.log_exception_with_context(
                        e,
                        {"operation": "api_call", "error_type": error_type},
                        "api_client",
                        "request",
                    )
                    error_aggregator.add_error(error_context)

        # Analyze error trends
        trends = error_aggregator.get_error_trends(time_window_hours=1)
        assert trends["total_errors"] >= 9
        assert len(trends["top_errors"]) > 0

        # Check for critical patterns
        critical_patterns = error_aggregator.identify_critical_patterns()
        if trends["error_rate_per_hour"] > 10:
            assert any(p["type"] == "high_error_rate" for p in critical_patterns)


class TestDataValidationErrors:
    """Test invalid data handling and malformed responses."""

    def test_market_data_validation_errors(self):
        """Test validation of invalid market data."""
        invalid_market_data_scenarios = [
            # Missing required fields
            {
                "symbol": "BTC-USD",
                "timestamp": datetime.now(UTC),
                # Missing OHLCV data
            },
            # Invalid price values
            {
                "symbol": "BTC-USD",
                "timestamp": datetime.now(UTC),
                "open": Decimal(-100),  # Negative price
                "high": Decimal(50000),
                "low": Decimal(49000),
                "close": Decimal(50000),
                "volume": Decimal(100),
            },
            # Invalid OHLC relationships
            {
                "symbol": "BTC-USD",
                "timestamp": datetime.now(UTC),
                "open": Decimal(50000),
                "high": Decimal(49000),  # High < Open
                "low": Decimal(51000),  # Low > Open
                "close": Decimal(50000),
                "volume": Decimal(100),
            },
            # Invalid volume
            {
                "symbol": "BTC-USD",
                "timestamp": datetime.now(UTC),
                "open": Decimal(50000),
                "high": Decimal(50100),
                "low": Decimal(49900),
                "close": Decimal(50000),
                "volume": Decimal(-50),  # Negative volume
            },
        ]

        for i, invalid_data in enumerate(invalid_market_data_scenarios):
            with pytest.raises((ValueError, TypeError, KeyError)) as exc_info:
                MarketData(**invalid_data)

            error_msg = str(exc_info.value).lower()
            assert any(
                keyword in error_msg
                for keyword in ["invalid", "missing", "negative", "required"]
            ), f"Scenario {i}: Unexpected error message: {error_msg}"

    def test_decimal_precision_errors(self):
        """Test handling of decimal precision and overflow errors."""
        precision_scenarios = [
            "999999999999999999999999999999999999999999999",  # Too large
            "0.000000000000000000000000000000000000001",  # Too precise
            "NaN",  # Not a number
            "Infinity",  # Infinity
            "-Infinity",  # Negative infinity
            "invalid_decimal",  # Invalid format
        ]

        for scenario in precision_scenarios:
            with pytest.raises((InvalidOperation, ValueError, OverflowError)):
                result = Decimal(scenario)
                # Try to use the decimal in calculations
                result * Decimal(2)

    def test_json_parsing_errors(self):
        """Test handling of malformed JSON responses."""
        malformed_json_scenarios = [
            '{"incomplete": json',  # Incomplete JSON
            '{"invalid": "json"',  # Missing closing brace
            '{"duplicate": 1, "duplicate": 2}',  # Duplicate keys (valid JSON but problematic)
            "not json at all",  # Not JSON
            "",  # Empty string
            '{"nested": {"broken": }',  # Broken nested structure
            '{"numbers": [1, 2, 3,]}',  # Trailing comma
        ]

        for scenario in malformed_json_scenarios:
            with pytest.raises(json.JSONDecodeError):
                json.loads(scenario)

    def test_trade_action_validation_errors(self):
        """Test validation of invalid trade actions."""
        invalid_trade_actions = [
            # Invalid action
            {"action": "INVALID_ACTION", "size_pct": 10, "rationale": "test"},
            # Invalid size
            {"action": "LONG", "size_pct": -10, "rationale": "test"},
            {"action": "LONG", "size_pct": 150, "rationale": "test"},  # > 100%
            # Missing required fields
            {"action": "LONG", "size_pct": 10},  # Missing rationale
            # Invalid stop loss/take profit
            {
                "action": "LONG",
                "size_pct": 10,
                "stop_loss_pct": -5,  # Negative
                "take_profit_pct": 3,
                "rationale": "test",
            },
        ]

        for invalid_action in invalid_trade_actions:
            with pytest.raises((ValueError, TypeError)) as exc_info:
                TradeAction(**invalid_action)

            # Verify error message is meaningful
            error_msg = str(exc_info.value).lower()
            assert any(
                keyword in error_msg
                for keyword in ["invalid", "required", "missing", "validation"]
            )

    def test_order_data_corruption_handling(self):
        """Test handling of corrupted order data."""
        corrupted_order_scenarios = [
            # Invalid status
            {
                "id": "test_123",
                "symbol": "BTC-USD",
                "side": "BUY",
                "type": "MARKET",
                "quantity": Decimal("0.1"),
                "price": Decimal(50000),
                "status": "INVALID_STATUS",  # Not in OrderStatus enum
                "timestamp": datetime.now(UTC),
            },
            # Inconsistent filled quantity
            {
                "id": "test_123",
                "symbol": "BTC-USD",
                "side": "BUY",
                "type": "MARKET",
                "quantity": Decimal("0.1"),
                "price": Decimal(50000),
                "status": OrderStatus.FILLED,
                "timestamp": datetime.now(UTC),
                "filled_quantity": Decimal("0.2"),  # More than ordered
            },
        ]

        for corrupted_data in corrupted_order_scenarios:
            with pytest.raises((ValueError, TypeError)):
                Order(**corrupted_data)


class TestWebSocketErrorHandling:
    """Test WebSocket disconnections and recovery mechanisms."""

    @pytest.fixture
    def websocket_simulator(self):
        """WebSocket failure simulator fixture."""
        return WebSocketFailureSimulator()

    @pytest.mark.asyncio
    async def test_websocket_connection_failures(self, websocket_simulator):
        """Test WebSocket connection failure scenarios."""
        failure_modes = ["connection_refused", "invalid_uri", "ssl_error"]

        for mode in failure_modes:
            websocket_simulator.set_connection_mode(mode)

            with pytest.raises(Exception) as exc_info:
                await websocket_simulator.simulate_connection("wss://test.com")

            # Verify appropriate error type
            error_msg = str(exc_info.value).lower()
            if mode == "connection_refused":
                assert "refused" in error_msg
            elif mode == "invalid_uri":
                assert "invalid" in error_msg or "uri" in error_msg
            elif mode == "ssl_error":
                assert "ssl" in error_msg

    @pytest.mark.asyncio
    async def test_websocket_message_corruption(self, websocket_simulator):
        """Test handling of corrupted WebSocket messages."""
        websocket_simulator.set_connection_mode(
            "message_corruption", corruption_rate=0.5
        )

        websocket = await websocket_simulator.simulate_connection("wss://test.com")

        corrupted_count = 0
        valid_count = 0

        for _ in range(10):
            try:
                message = await websocket.recv()
                # Try to parse as JSON
                data = json.loads(message)
                if "type" in data and "symbol" in data:
                    valid_count += 1
                else:
                    corrupted_count += 1
            except (json.JSONDecodeError, KeyError):
                corrupted_count += 1

        assert corrupted_count > 0  # Should have some corruption
        assert valid_count > 0  # Should have some valid messages

    @pytest.mark.asyncio
    async def test_websocket_periodic_disconnections(self, websocket_simulator):
        """Test handling of periodic WebSocket disconnections."""
        websocket_simulator.set_connection_mode(
            "periodic_disconnect", disconnect_after=3
        )

        websocket = await websocket_simulator.simulate_connection("wss://test.com")

        message_count = 0

        # Should receive messages until disconnection
        try:
            while True:
                await websocket.recv()
                message_count += 1
        except ConnectionClosed:
            pass  # Expected disconnection

        assert message_count >= 3  # Should have received messages before disconnect

    @pytest.mark.asyncio
    async def test_websocket_reconnection_logic(self, websocket_simulator):
        """Test WebSocket reconnection logic."""
        max_reconnect_attempts = 3
        reconnect_delay = 0.1

        for attempt in range(max_reconnect_attempts):
            try:
                websocket_simulator.set_connection_mode("connection_refused")
                websocket = await websocket_simulator.simulate_connection(
                    "wss://test.com"
                )
                break  # Success
            except Exception as e:
                if attempt == max_reconnect_attempts - 1:
                    # Final attempt failed
                    assert "refused" in str(e).lower()
                    break
                # Wait before retry
                await asyncio.sleep(reconnect_delay)

        # Verify retry attempts were made
        assert attempt >= 0


class TestConfigurationErrorHandling:
    """Test configuration errors and validation."""

    def test_missing_environment_variables(self):
        """Test handling of missing required environment variables."""
        required_env_vars = [
            "COINBASE_API_KEY",
            "COINBASE_PRIVATE_KEY",
            "LLM_OPENAI_API_KEY",
        ]

        for env_var in required_env_vars:
            # Temporarily remove environment variable
            original_value = os.environ.get(env_var)
            if env_var in os.environ:
                del os.environ[env_var]

            try:
                # Test configuration loading fails appropriately
                from bot.fp.types.config import Config

                result = Config.from_env()

                # Should fail validation
                assert result.is_failure()
                failure_msg = str(result.failure()).lower()
                assert any(
                    keyword in failure_msg
                    for keyword in [
                        "missing",
                        "required",
                        "environment",
                        env_var.lower(),
                    ]
                )

            finally:
                # Restore environment variable
                if original_value is not None:
                    os.environ[env_var] = original_value

    def test_invalid_configuration_values(self):
        """Test handling of invalid configuration values."""
        invalid_config_scenarios = [
            # Invalid trading mode
            {"TRADING_MODE": "invalid_mode"},
            # Invalid exchange type
            {"EXCHANGE_TYPE": "nonexistent_exchange"},
            # Invalid numeric values
            {"TRADING_LEVERAGE": "not_a_number"},
            {"MAX_CONCURRENT_POSITIONS": "-1"},
            {"DEFAULT_POSITION_SIZE": "1.5"},  # > 1.0
            # Invalid boolean values
            {"ENABLE_WEBSOCKET": "maybe"},
            {"ENABLE_MEMORY": "yes_please"},
        ]

        for invalid_config in invalid_config_scenarios:
            # Temporarily set invalid config
            original_values = {}
            for key, value in invalid_config.items():
                original_values[key] = os.environ.get(key)
                os.environ[key] = value

            try:
                from bot.fp.types.config import Config

                result = Config.from_env()

                # Should fail validation
                assert result.is_failure()

            finally:
                # Restore original values
                for key, original_value in original_values.items():
                    if original_value is not None:
                        os.environ[key] = original_value
                    elif key in os.environ:
                        del os.environ[key]

    def test_configuration_security_validation(self):
        """Test security validation of configuration."""
        security_issues = [
            # Exposed API keys in logs
            {"COINBASE_API_KEY": "plaintext_key_visible"},
            # Weak private keys
            {"COINBASE_PRIVATE_KEY": "weak_key_123"},
            # Insecure endpoints
            {"COINBASE_API_URL": "http://insecure.api.com"},  # HTTP instead of HTTPS
        ]

        for security_config in security_issues:
            # Check that security validation catches issues
            original_values = {}
            for key, value in security_config.items():
                original_values[key] = os.environ.get(key)
                os.environ[key] = value

            try:
                from bot.fp.types.config import Config

                result = Config.from_env()

                if result.is_success():
                    config = result.success()
                    # Verify sensitive data is masked in string representation
                    config_str = str(config)
                    assert "plaintext_key_visible" not in config_str
                    assert "weak_key_123" not in config_str

            finally:
                # Restore original values
                for key, original_value in original_values.items():
                    if original_value is not None:
                        os.environ[key] = original_value
                    elif key in os.environ:
                        del os.environ[key]


class TestResourceExhaustionScenarios:
    """Test resource exhaustion and memory pressure scenarios."""

    def test_memory_pressure_handling(self):
        """Test handling of memory pressure scenarios."""
        # Create large data structure to simulate memory pressure
        large_data_size = 1000000  # 1M elements

        try:
            # Simulate large market data processing
            large_data = []
            for i in range(large_data_size):
                large_data.append(
                    {
                        "timestamp": datetime.now(UTC),
                        "price": Decimal(f"{50000 + i}"),
                        "volume": Decimal(100),
                        "metadata": f"data_point_{i}" * 10,  # Additional memory usage
                    }
                )

            # Process data in chunks to avoid memory issues
            chunk_size = 10000
            processed_chunks = 0

            for i in range(0, len(large_data), chunk_size):
                chunk = large_data[i : i + chunk_size]
                # Simulate processing
                processed_chunks += 1

                # Clean up chunk to free memory
                del chunk

            assert processed_chunks == (large_data_size // chunk_size)

        except MemoryError:
            # If we hit memory limits, ensure graceful handling
            pytest.skip("Insufficient memory for test")

    def test_file_descriptor_exhaustion(self):
        """Test handling of file descriptor exhaustion."""
        # Simulate opening many connections/files
        connections = []
        max_connections = 100

        try:
            for i in range(max_connections):
                # Simulate creating connection objects
                connection = Mock()
                connection.connected = True
                connection.id = f"conn_{i}"
                connections.append(connection)

            # Ensure proper cleanup
            assert len(connections) == max_connections

        finally:
            # Clean up all connections
            for conn in connections:
                conn.connected = False
            connections.clear()

    def test_cpu_intensive_operation_handling(self):
        """Test handling of CPU-intensive operations."""

        def cpu_intensive_calculation(n: int) -> int:
            """Simulate CPU-intensive calculation."""
            total = 0
            for i in range(n):
                total += i * i
            return total

        # Test with timeout to prevent hanging
        start_time = time.time()
        result = cpu_intensive_calculation(1000000)
        end_time = time.time()

        # Should complete in reasonable time
        assert end_time - start_time < 5.0  # 5 second timeout
        assert result > 0

    def test_concurrent_resource_access(self):
        """Test handling of concurrent resource access."""
        shared_resource = {"counter": 0, "data": []}
        lock = threading.Lock()

        def worker_function(worker_id: int):
            """Worker function that accesses shared resource."""
            for _ in range(100):
                with lock:
                    shared_resource["counter"] += 1
                    shared_resource["data"].append(f"worker_{worker_id}")

        # Create multiple threads accessing shared resource
        threads = []
        num_workers = 10

        for i in range(num_workers):
            thread = threading.Thread(target=worker_function, args=(i,))
            threads.append(thread)
            thread.start()

        # Wait for all threads to complete
        for thread in threads:
            thread.join()

        # Verify resource integrity
        assert shared_resource["counter"] == num_workers * 100
        assert len(shared_resource["data"]) == num_workers * 100


class TestCircuitBreakerPatterns:
    """Test circuit breaker patterns and failure isolation."""

    def test_trading_circuit_breaker_states(self):
        """Test circuit breaker state transitions."""
        circuit_breaker = TradingCircuitBreaker(failure_threshold=3, timeout_seconds=1)

        # Initial state should be CLOSED
        assert circuit_breaker.state == "CLOSED"
        assert circuit_breaker.can_execute_trade()

        # Record failures to trigger OPEN state
        for i in range(3):
            circuit_breaker.record_failure("order_failure", f"Order failed {i + 1}")

        # Should now be OPEN
        assert circuit_breaker.state == "OPEN"
        assert not circuit_breaker.can_execute_trade()

        # Wait for timeout
        time.sleep(1.1)

        # Should allow HALF_OPEN
        assert circuit_breaker.can_execute_trade()

        # Success should close circuit
        circuit_breaker.record_success()
        assert circuit_breaker.state == "CLOSED"

    def test_circuit_breaker_with_different_severities(self):
        """Test circuit breaker behavior with different error severities."""
        circuit_breaker = TradingCircuitBreaker(failure_threshold=5, timeout_seconds=1)

        # Critical error should immediately open circuit
        circuit_breaker.record_failure("critical_error", "System failure", "critical")
        assert circuit_breaker.state == "OPEN"

        # Reset for next test
        circuit_breaker = TradingCircuitBreaker(failure_threshold=5, timeout_seconds=1)

        # Multiple low-severity errors should accumulate
        for i in range(5):
            circuit_breaker.record_failure("minor_error", f"Minor issue {i + 1}", "low")

        assert circuit_breaker.state == "OPEN"

    def test_error_boundary_isolation(self):
        """Test error boundary pattern for component isolation."""

        async def failing_operation():
            raise ValueError("Component failed")

        async def fallback_operation(error, context):
            return f"Fallback executed due to: {error}"

        # Test error boundary contains errors
        boundary = ErrorBoundary(
            component_name="test_component",
            fallback_behavior=fallback_operation,
            max_retries=2,
            severity=ErrorSeverity.HIGH,
        )

        # Error should be contained within boundary
        async with boundary:
            await failing_operation()

        assert boundary.error_count > 0
        assert boundary.last_error is not None

    def test_trade_saga_compensation(self):
        """Test trade saga pattern with compensation actions."""
        saga = TradeSaga("test_trade_saga")

        executed_steps = []
        compensated_steps = []

        def step1():
            executed_steps.append("step1")
            return "step1_result"

        def step2():
            executed_steps.append("step2")
            return "step2_result"

        def step3():
            executed_steps.append("step3")
            raise Exception("Step 3 failed")  # This will trigger compensation

        def compensate1(result):
            compensated_steps.append("compensate1")

        def compensate2(result):
            compensated_steps.append("compensate2")

        # Add saga steps with compensation
        saga.add_step(step1, compensate1, "Initialize position")
        saga.add_step(step2, compensate2, "Place order")
        saga.add_step(step3, None, "Confirm execution")

        # Execute saga (should fail at step 3)
        with pytest.raises(Exception) as exc_info:
            asyncio.run(saga.execute())

        assert "Step 3 failed" in str(exc_info.value)

        # Verify compensation was executed
        assert "step1" in executed_steps
        assert "step2" in executed_steps
        assert "step3" in executed_steps
        assert "compensate2" in compensated_steps
        assert "compensate1" in compensated_steps

        # Verify saga status
        status = saga.get_status()
        assert status["status"] == "failed"
        assert status["completed_steps"] == 2  # step1 and step2 completed


class TestErrorPropagationAndLogging:
    """Test error propagation and logging mechanisms."""

    def test_error_context_logging(self):
        """Test comprehensive error context logging."""
        from bot.error_handling import exception_handler

        try:
            # Simulate operation that fails
            raise ValueError("Test error for logging")
        except Exception as e:
            error_context = exception_handler.log_exception_with_context(
                e,
                {
                    "operation": "test_operation",
                    "user_id": "test_user",
                    "timestamp": datetime.now().isoformat(),
                    "additional_data": {"key": "value"},
                },
                component="test_component",
                operation="test_function",
            )

        # Verify error context contains all necessary information
        assert error_context.component == "test_component"
        assert error_context.operation == "test_function"
        assert error_context.error_type == "ValueError"
        assert "Test error for logging" in error_context.error_message
        assert error_context.context_data["operation"] == "test_operation"

    def test_balance_error_handling_specifics(self):
        """Test specialized balance error handling."""
        balance_handler = BalanceErrorHandler(exception_handler)

        # Test different balance error types
        balance_errors = [
            InsufficientBalanceError("Insufficient funds for trade"),
            BalanceServiceUnavailableError("Balance service temporarily down"),
            BalanceTimeoutError("Balance request timed out"),
            BalanceValidationError("Invalid balance data received"),
            BalanceRetrievalError("Failed to retrieve account balance"),
        ]

        for error in balance_errors:
            recommendations = balance_handler.handle_balance_error(
                error,
                {"symbol": "BTC-USD", "requested_amount": "1000.0"},
                "balance_test_component",
            )

            # Verify appropriate recommendations based on error type
            if isinstance(error, InsufficientBalanceError):
                assert recommendations["action"] == "check_balance"
                assert recommendations["user_action_required"] == "true"
            elif isinstance(error, BalanceServiceUnavailableError):
                assert recommendations["action"] == "retry_with_backoff"
                assert "exponential_backoff" in recommendations["retry_strategy"]
            elif isinstance(error, BalanceTimeoutError):
                assert recommendations["action"] == "retry_with_reduced_timeout"
            elif isinstance(error, BalanceValidationError):
                assert recommendations["action"] == "log_and_fallback"
                assert recommendations["escalation_required"] == "true"

    def test_graceful_degradation_scenarios(self):
        """Test graceful degradation when services fail."""
        degradation = GracefulDegradation()

        # Register services with fallback strategies
        def primary_llm_service(*args, **kwargs):
            raise Exception("LLM service unavailable")

        def fallback_llm_service(*args, **kwargs):
            return {"action": "HOLD", "confidence": 0.5, "degraded": True}

        def primary_data_service(*args, **kwargs):
            raise ConnectionError("Data service connection failed")

        def fallback_data_service(*args, **kwargs):
            return {"cached_data": True, "timestamp": datetime.now().isoformat()}

        degradation.register_service(
            "llm", fallback_llm_service, degradation_threshold=2
        )
        degradation.register_service(
            "data", fallback_data_service, degradation_threshold=3
        )

        # Test fallback execution
        llm_result = asyncio.run(
            degradation.execute_with_fallback("llm", primary_llm_service, "test_input")
        )
        assert llm_result["degraded"] is True

        data_result = asyncio.run(
            degradation.execute_with_fallback(
                "data", primary_data_service, "test_symbol"
            )
        )
        assert data_result["cached_data"] is True

        # Verify services are marked as degraded after threshold
        llm_health = degradation.get_service_status("llm")
        assert llm_health is not None
        assert llm_health.failure_count > 0


class TestRecoveryMechanisms:
    """Test error recovery and resilience mechanisms."""

    @pytest.mark.asyncio
    async def test_automatic_recovery_from_transient_errors(self):
        """Test automatic recovery from transient errors."""
        recovery_count = 0

        class TransientError(Exception):
            pass

        async def unreliable_operation():
            nonlocal recovery_count
            recovery_count += 1
            if recovery_count <= 2:
                raise TransientError(f"Transient failure {recovery_count}")
            return f"Success after {recovery_count} attempts"

        # Test with retry mechanism
        @retry_with_backoff(
            max_retries=3, base_delay=0.01, exceptions=(TransientError,)
        )
        async def recovered_operation():
            return await unreliable_operation()

        result = await recovered_operation()
        assert "Success after 3 attempts" in result
        assert recovery_count == 3

    def test_error_recovery_strategy_adaptation(self):
        """Test adaptive error recovery strategies."""
        strategy = create_error_recovery_strategy(
            max_retries=3,
            base_delay=timedelta(milliseconds=100),
            max_delay=timedelta(seconds=5),
            backoff_multiplier=2.0,
        )

        # Test strategy adapts to error types
        failure_count = 0

        def adaptive_operation() -> IOEither[Exception, str]:
            nonlocal failure_count
            failure_count += 1

            if failure_count <= 2:
                return IOEither.left(NetworkError("Network unstable", "NETWORK_ERROR"))
            return IOEither.right("Network recovered")

        result = strategy.apply(adaptive_operation)

        # Should eventually succeed
        final_result = result.run()
        if final_result.is_right():
            assert "Network recovered" in final_result.value

    @pytest.mark.asyncio
    async def test_cascade_failure_prevention(self):
        """Test prevention of cascade failures."""
        # Simulate interconnected services
        service_states = {
            "service_a": "healthy",
            "service_b": "healthy",
            "service_c": "healthy",
        }

        async def service_operation(service_name: str):
            state = service_states[service_name]
            if state == "failed":
                raise Exception(f"{service_name} is down")
            if state == "degraded":
                await asyncio.sleep(0.1)  # Slower response
                return f"{service_name} degraded response"
            return f"{service_name} normal response"

        # Simulate cascade failure
        service_states["service_a"] = "failed"

        # Other services should detect failure and degrade gracefully
        try:
            await service_operation("service_a")
        except Exception:
            # Service B and C should continue operating
            service_states["service_b"] = "degraded"
            service_states["service_c"] = "degraded"

        # Verify other services still function
        result_b = await service_operation("service_b")
        result_c = await service_operation("service_c")

        assert "degraded" in result_b
        assert "degraded" in result_c


if __name__ == "__main__":
    pytest.main([__file__, "-v", "--tb=short"])
